Workbook

Sheet Monthly P&L
B1: M1 | C1: M2 | D1: M3 | E1: M4 | F1: M5 | G1: M6 | H1: M7 | I1: M8 | J1: M9 | K1: M10 | L1: M11 | M1: M12 | N1: TOTAL
A2: ASSUMPTIONS
A3: Variable API % | B3: 0.05 | C3: 0.05 | D3: 0.05 | E3: 0.05 | F3: 0.05 | G3: 0.05 | H3: 0.05 | I3: 0.05 | J3: 0.05 | K3: 0.05 | L3: 0.05 | M3: 0.05
A4: Commission % | B4: 0.25 | C4: 0.25 | D4: 0.25 | E4: 0.25 | F4: 0.25 | G4: 0.25 | H4: 0.25 | I4: 0.25 | J4: 0.25 | K4: 0.25 | L4: 0.25 | M4: 0.25
A5: Tax Rate | B5: 0.15 | C5: 0.15 | D5: 0.15 | E5: 0.15 | F5: 0.15 | G5: 0.15 | H5: 0.15 | I5: 0.15 | J5: 0.15 | K5: 0.15 | L5: 0.15 | M5: 0.15
A6: Equipment per Hire | B6: 1000 | C6: 1000 | D6: 1000 | E6: 1000 | F6: 1000 | G6: 1000 | H6: 1000 | I6: 1000 | J6: 1000 | K6: 1000 | L6: 1000 | M6: 1000
A7: Revenue per Client | B7: 300 | C7: 300 | D7: 300 | E7: 300 | F7: 300 | G7: 300 | H7: 300 | I7: 300 | J7: 300 | K7: 300 | L7: 300 | M7: 300
A9: HEADCOUNT
A10: Sales Team | B10: 6 | C10: 6 | D10: 6 | E10: 8 | F10: 8 | G10: 10 | H10: 10 | I10: 12 | J10: 12 | K10: 13 | L10: 14 | M10: 15 | N10: =M10 -> 15
A11: Tech Team | B11: 2 | C11: 2 | D11: 2 | E11: 2 | F11: 2 | G11: 3 | H11: 3 | I11: 3 | J11: 3 | K11: 4 | L11: 4 | M11: 4 | N11: =M11 -> 4
A12: New Tech Hires | B12: =B11 -> 2 | C12: =MAX(0,C11-B11) -> 0 | D12: =MAX(0,D11-C11) -> 0 | E12: =MAX(0,E11-D11) -> 0 | F12: =MAX(0,F11-E11) -> 0 | G12: =MAX(0,G11-F11) -> 1 | H12: =MAX(0,H11-G11) -> 0 | I12: =MAX(0,I11-H11) -> 0 | J12: =MAX(0,J11-I11) -> 0 | ... M12: =MAX(0,M11-L11) -> 0
A14: CLIENTS
A15: Starting Clients | B15: 10 | C15: =B18 -> 27 | D15: =C18 -> 43 | E15: =D18 -> 58 | F15: =E18 -> 75 | G15: =F18 -> 94 | H15: =G18 -> 115 | I15: =H18 -> 137 | J15: =I18 -> 161 | ... M15: =L18 -> 237
A16: New Clients | B16: 18 | C16: 18 | D16: 18 | E16: 21 | F16: 24 | G16: 27 | H16: 30 | I16: 33 | J16: 36 | K16: 37 | L16: 40 | M16: 43 | N16: =SUM(B16:M16) -> 345
A17: Churned | B17: 1 | C17: 2 | D17: 3 | E17: 4 | F17: 5 | G17: 6 | H17: 8 | I17: 9 | J17: 11 | K17: 12 | L17: 14 | M17: 16 | N17: =SUM(B17:M17) -> 91
A18: Ending Clients | B18: =B15+B16-B17 -> 27 | C18: =C15+C16-C17 -> 43 | D18: =D15+D16-D17 -> 58 | E18: =E15+E16-E17 -> 75 | F18: =F15+F16-F17 -> 94 | G18: =G15+G16-G17 -> 115 | H18: =H15+H16-H17 -> 137 | I18: =I15+I16-I17 -> 161 | ... M18: =M15+M16-M17 -> 264 | N18: =M18 -> 264
A19: Avg Clients | B19: =(B15+B18)/2 -> 18.5 | C19: =(C15+C18)/2 -> 35 | D19: =(D15+D18)/2 -> 50.5 | E19: =(E15+E18)/2 -> 66.5 | F19: =(F15+F18)/2 -> 84.5 | G19: =(G15+G18)/2 -> 104.5 | H19: =(H15+H18)/2 -> 126 | I19: =(I15+I18)/2 -> 149 | ... M19: =(M15+M18)/2 -> 250.5
A21: REVENUE
A22: Total Revenue | B22: =B19*B7 -> 5550 | C22: =C19*C7 -> 10500 | D22: =D19*D7 -> 15150 | E22: =E19*E7 -> 19950 | F22: =F19*F7 -> 25350 | G22: =G19*G7 -> 31350 | H22: =H19*H7 -> 37800 | I22: =I19*I7 -> 44700 | ... M22: =M19*M7 -> 75150 | N22: =SUM(B22:M22) -> 444300
A24: COST OF REVENUE
A25: Infrastructure (Fixed + API) | B25: =600+B22*B3 -> 877.5 | C25: =600+C22*C3 -> 1125 | D25: =600+D22*D3 -> 1357.5 | E25: =600+E22*E3 -> 1597.5 | F25: =600+F22*F3 -> 1867.5 | G25: =600+G22*G3 -> 2167.5 | H25: =600+H22*H3 -> 2490 | I25: =600+I22*I3 -> 2835 | ... M25: =600+M22*M3 -> 4357.5 | N25: =SUM(B25:M25) -> 29415
A26: Sales Commission (25% Revenue Share) | B26: =B22*B4 -> 1387.5 | C26: =C22*C4 -> 2625 | D26: =D22*D4 -> 3787.5 | E26: =E22*E4 -> 4987.5 | F26: =F22*F4 -> 6337.5 | G26: =G22*G4 -> 7837.5 | H26: =H22*H4 -> 9450 | I26: =I22*I4 -> 11175 | ... M26: =M22*M4 -> 18787.5 | N26: =SUM(B26:M26) -> 111075
A27: Total COGS | B27: =B25+B26 -> 2265 | C27: =C25+C26 -> 3750 | D27: =D25+D26 -> 5145 | E27: =E25+E26 -> 6585 | F27: =F25+F26 -> 8205 | G27: =G25+G26 -> 10005 | H27: =H25+H26 -> 11940 | I27: =I25+I26 -> 14010 | ... M27: =M25+M26 -> 23145 | N27: =SUM(B27:M27) -> 140490
A29: GROSS PROFIT | B29: =B22-B27 -> 3285 | C29: =C22-C27 -> 6750 | D29: =D22-D27 -> 10005 | E29: =E22-E27 -> 13365 | F29: =F22-F27 -> 17145 | G29: =G22-G27 -> 21345 | H29: =H22-H27 -> 25860 | I29: =I22-I27 -> 30690 | ... M29: =M22-M27 -> 52005 | N29: =SUM(B29:M29) -> 303810
A30: Gross Margin % | B30: =IF(B22=0,0,B29/B22) -> 0.59189189 | C30: =IF(C22=0,0,C29/C22) -> 0.64285714 | D30: =IF(D22=0,0,D29/D22) -> 0.66039604 | E30: =IF(E22=0,0,E29/E22) -> 0.66992481 | F30: =IF(F22=0,0,F29/F22) -> 0.67633136 | G30: =IF(G22=0,0,G29/G22) -> 0.68086124 | H30: =IF(H22=0,0,H29/H22) -> 0.68412698 | I30: =IF(I22=0,0,I29/I22) -> 0.68657718 | ... N30: =IF(N22=0,0,N29/N22) -> 0.68379473
A32: OPERATING EXPENSES
A33: Tech Team Salaries | B33: 3000 | C33: 3000 | D33: 3000 | E33: 3000 | F33: 3000 | G33: 4500 | H33: 4500 | I33: 4500 | J33: 4500 | K33: 6000 | L33: 6000 | M33: 6000 | N33: =SUM(B33:M33) -> 51000
A34: Office & Admin | B34: 1500 | C34: 1500 | D34: 1500 | E34: 1500 | F34: 1500 | G34: 1500 | H34: 1500 | I34: 1500 | J34: 1500 | K34: 1500 | L34: 1500 | M34: 1500 | N34: =SUM(B34:M34) -> 18000
A35: Equipment | B35: =B12*B6 -> 2000 | C35: =C12*C6 -> 0 | D35: =D12*D6 -> 0 | E35: =E12*E6 -> 0 | F35: =F12*F6 -> 0 | G35: =G12*G6 -> 1000 | H35: =H12*H6 -> 0 | I35: =I12*I6 -> 0 | ... M35: =M12*M6 -> 0 | N35: =SUM(B35:M35) -> 4000
A36: Total OpEx | B36: =B33+B34+B35 -> 6500 | C36: =C33+C34+C35 -> 4500 | D36: =D33+D34+D35 -> 4500 | E36: =E33+E34+E35 -> 4500 | F36: =F33+F34+F35 -> 4500 | G36: =G33+G34+G35 -> 7000 | H36: =H33+H34+H35 -> 6000 | I36: =I33+I34+I35 -> 6000 | ... M36: =M33+M34+M35 -> 7500 | N36: =SUM(B36:M36) -> 73000
A38: EBITDA | B38: =B29-B36 -> -3215 | C38: =C29-C36 -> 2250 | D38: =D29-D36 -> 5505 | E38: =E29-E36 -> 8865 | F38: =F29-F36 -> 12645 | G38: =G29-G36 -> 14345 | H38: =H29-H36 -> 19860 | I38: =I29-I36 -> 24690 | ... M38: =M29-M36 -> 44505 | N38: =SUM(B38:M38) -> 230810
A39: EBITDA Margin % | B39: =IF(B22=0,0,B38/B22) -> -0.57927928 | C39: =IF(C22=0,0,C38/C22) -> 0.21428571 | D39: =IF(D22=0,0,D38/D22) -> 0.36336634 | E39: =IF(E22=0,0,E38/E22) -> 0.4443609 | F39: =IF(F22=0,0,F38/F22) -> 0.49881657 | G39: =IF(G22=0,0,G38/G22) -> 0.45757576 | H39: =IF(H22=0,0,H38/H22) -> 0.52539683 | I39: =IF(I22=0,0,I38/I22) -> 0.55234899 | ... N39: =IF(N22=0,0,N38/N22) -> 0.51949133
A41: Taxes/Reserves | B41: =IF(B38>0,B38*B5,0) -> 0 | C41: =IF(C38>0,C38*C5,0) -> 337.5 | D41: =IF(D38>0,D38*D5,0) -> 825.75 | E41: =IF(E38>0,E38*E5,0) -> 1329.75 | F41: =IF(F38>0,F38*F5,0) -> 1896.75 | G41: =IF(G38>0,G38*G5,0) -> 2151.75 | H41: =IF(H38>0,H38*H5,0) -> 2979 | I41: =IF(I38>0,I38*I5,0) -> 3703.5 | ... M41: =IF(M38>0,M38*M5,0) -> 6675.75 | N41: =SUM(B41:M41) -> 35103.75
A42: NET INCOME | B42: =B38-B41 -> -3215 | C42: =C38-C41 -> 1912.5 | D42: =D38-D41 -> 4679.25 | E42: =E38-E41 -> 7535.25 | F42: =F38-F41 -> 10748.25 | G42: =G38-G41 -> 12193.25 | H42: =H38-H41 -> 16881 | I42: =I38-I41 -> 20986.5 | ... M42: =M38-M41 -> 37829.25 | N42: =SUM(B42:M42) -> 195706.25
A44: KEY METRICS
A45: Cumulative Revenue | B45: =B22 -> 5550 | C45: =B45+C22 -> 16050 | D45: =C45+D22 -> 31200 | E45: =D45+E22 -> 51150 | F45: =E45+F22 -> 76500 | G45: =F45+G22 -> 107850 | H45: =G45+H22 -> 145650 | I45: =H45+I22 -> 190350 | J45: =I45+J22 -> 242400 | ... M45: =L45+M22 -> 444300 | N45: =M45 -> 444300
A46: Cash Balance | B46: =B42 -> -3215 | C46: =B46+C42 -> -1302.5 | D46: =C46+D42 -> 3376.75 | E46: =D46+E42 -> 10912 | F46: =E46+F42 -> 21660.25 | G46: =F46+G42 -> 33853.5 | H46: =G46+H42 -> 50734.5 | I46: =H46+I42 -> 71721 | J46: =I46+J42 -> 97080.75 | ... M46: =L46+M42 -> 195706.25 | N46: =M46 -> 195706.25

Sheet Client Growth
B1: M1 | C1: M2 | D1: M3 | E1: M4 | F1: M5 | G1: M6 | H1: M7 | I1: M8 | J1: M9 | K1: M10 | L1: M11 | M1: M12 | N1: TOTAL
A2: CLIENT METRICS
A3: Starting Clients | B3: ='Monthly P&L'!B15 -> 10 | C3: ='Monthly P&L'!C15 -> 27 | D3: ='Monthly P&L'!D15 -> 43 | E3: ='Monthly P&L'!E15 -> 58 | F3: ='Monthly P&L'!F15 -> 75 | G3: ='Monthly P&L'!G15 -> 94 | H3: ='Monthly P&L'!H15 -> 115 | I3: ='Monthly P&L'!I15 -> 137 | ... M3: ='Monthly P&L'!M15 -> 237
A4: New Clients | B4: ='Monthly P&L'!B16 -> 18 | C4: ='Monthly P&L'!C16 -> 18 | D4: ='Monthly P&L'!D16 -> 18 | E4: ='Monthly P&L'!E16 -> 21 | F4: ='Monthly P&L'!F16 -> 24 | G4: ='Monthly P&L'!G16 -> 27 | H4: ='Monthly P&L'!H16 -> 30 | I4: ='Monthly P&L'!I16 -> 33 | ... M4: ='Monthly P&L'!M16 -> 43 | N4: =SUM(B4:M4) -> 345
A5: Churned | B5: ='Monthly P&L'!B17 -> 1 | C5: ='Monthly P&L'!C17 -> 2 | D5: ='Monthly P&L'!D17 -> 3 | E5: ='Monthly P&L'!E17 -> 4 | F5: ='Monthly P&L'!F17 -> 5 | G5: ='Monthly P&L'!G17 -> 6 | H5: ='Monthly P&L'!H17 -> 8 | I5: ='Monthly P&L'!I17 -> 9 | ... M5: ='Monthly P&L'!M17 -> 16 | N5: =SUM(B5:M5) -> 91
A6: Ending Clients | B6: ='Monthly P&L'!B18 -> 27 | C6: ='Monthly P&L'!C18 -> 43 | D6: ='Monthly P&L'!D18 -> 58 | E6: ='Monthly P&L'!E18 -> 75 | F6: ='Monthly P&L'!F18 -> 94 | G6: ='Monthly P&L'!G18 -> 115 | H6: ='Monthly P&L'!H18 -> 137 | I6: ='Monthly P&L'!I18 -> 161 | ... M6: ='Monthly P&L'!M18 -> 264 | N6: =M6 -> 264
A7: Net Additions | B7: =B4-B5 -> 17 | C7: =C4-C5 -> 16 | D7: =D4-D5 -> 15 | E7: =E4-E5 -> 17 | F7: =F4-F5 -> 19 | G7: =G4-G5 -> 21 | H7: =H4-H5 -> 22 | I7: =I4-I5 -> 24 | ... M7: =M4-M5 -> 27 | N7: =SUM(B7:M7) -> 254
A8: MoM Growth % | B8: N/A | C8: =IF(B6=0,0,(C6-B6)/B6) -> 0.59259259 | D8: =IF(C6=0,0,(D6-C6)/C6) -> 0.34883721 | E8: =IF(D6=0,0,(E6-D6)/D6) -> 0.29310345 | F8: =IF(E6=0,0,(F6-E6)/E6) -> 0.25333333 | G8: =IF(F6=0,0,(G6-F6)/F6) -> 0.22340426 | H8: =IF(G6=0,0,(H6-G6)/G6) -> 0.19130435 | I8: =IF(H6=0,0,(I6-H6)/H6) -> 0.17518248 | J8: =IF(I6=0,0,(J6-I6)/I6) -> 0.1552795 | ... M8: =IF(L6=0,0,(M6-L6)/L6) -> 0.11392405
A10: SALES METRICS
A11: Sales Team | B11: ='Monthly P&L'!B10 -> 6 | C11: ='Monthly P&L'!C10 -> 6 | D11: ='Monthly P&L'!D10 -> 6 | E11: ='Monthly P&L'!E10 -> 8 | F11: ='Monthly P&L'!F10 -> 8 | G11: ='Monthly P&L'!G10 -> 10 | H11: ='Monthly P&L'!H10 -> 10 | I11: ='Monthly P&L'!I10 -> 12 | ... M11: ='Monthly P&L'!M10 -> 15 | N11: =M11 -> 15
A12: New Sales Hires | B12: =B11 -> 6 | C12: =MAX(0,C11-B11) -> 0 | D12: =MAX(0,D11-C11) -> 0 | E12: =MAX(0,E11-D11) -> 2 | F12: =MAX(0,F11-E11) -> 0 | G12: =MAX(0,G11-F11) -> 2 | H12: =MAX(0,H11-G11) -> 0 | I12: =MAX(0,I11-H11) -> 2 | J12: =MAX(0,J11-I11) -> 0 | ... M12: =MAX(0,M11-L11) -> 1
A13: Deals per Person | B13: =IF(B11=0,0,B4/B11) -> 3 | C13: =IF(C11=0,0,C4/C11) -> 3 | D13: =IF(D11=0,0,D4/D11) -> 3 | E13: =IF(E11=0,0,E4/E11) -> 2.625 | F13: =IF(F11=0,0,F4/F11) -> 3 | G13: =IF(G11=0,0,G4/G11) -> 2.7 | H13: =IF(H11=0,0,H4/H11) -> 3 | I13: =IF(I11=0,0,I4/I11) -> 2.75 | ... M13: =IF(M11=0,0,M4/M11) -> 2.8666667
A15: CHURN ANALYSIS
A16: Churn Rate % | B16: =IF(B3=0,0,B5/B3) -> 0.1 | C16: =IF(C3=0,0,C5/C3) -> 0.074074074 | D16: =IF(D3=0,0,D5/D3) -> 0.069767442 | E16: =IF(E3=0,0,E5/E3) -> 0.068965517 | F16: =IF(F3=0,0,F5/F3) -> 0.066666667 | G16: =IF(G3=0,0,G5/G3) -> 0.063829787 | H16: =IF(H3=0,0,H5/H3) -> 0.069565217 | I16: =IF(I3=0,0,I5/I3) -> 0.065693431 | ... M16: =IF(M3=0,0,M5/M3) -> 0.067510549
A17: Avg Monthly Churn | B17: =AVERAGE(B16:M16) -> 0.070438542

Sheet Team & Costs
B1: M1 | C1: M2 | D1: M3 | E1: M4 | F1: M5 | G1: M6 | H1: M7 | I1: M8 | J1: M9 | K1: M10 | L1: M11 | M1: M12 | N1: TOTAL
A2: HEADCOUNT
A3: Sales Team | B3: ='Monthly P&L'!B10 -> 6 | C3: ='Monthly P&L'!C10 -> 6 | D3: ='Monthly P&L'!D10 -> 6 | E3: ='Monthly P&L'!E10 -> 8 | F3: ='Monthly P&L'!F10 -> 8 | G3: ='Monthly P&L'!G10 -> 10 | H3: ='Monthly P&L'!H10 -> 10 | I3: ='Monthly P&L'!I10 -> 12 | ... M3: ='Monthly P&L'!M10 -> 15 | N3: =M3 -> 15
A4: Tech Team | B4: ='Monthly P&L'!B11 -> 2 | C4: ='Monthly P&L'!C11 -> 2 | D4: ='Monthly P&L'!D11 -> 2 | E4: ='Monthly P&L'!E11 -> 2 | F4: ='Monthly P&L'!F11 -> 2 | G4: ='Monthly P&L'!G11 -> 3 | H4: ='Monthly P&L'!H11 -> 3 | I4: ='Monthly P&L'!I11 -> 3 | ... M4: ='Monthly P&L'!M11 -> 4 | N4: =M4 -> 4
A5: Total Headcount | B5: =B3+B4 -> 8 | C5: =C3+C4 -> 8 | D5: =D3+D4 -> 8 | E5: =E3+E4 -> 10 | F5: =F3+F4 -> 10 | G5: =G3+G4 -> 13 | H5: =H3+H4 -> 13 | I5: =I3+I4 -> 15 | ... M5: =M3+M4 -> 19 | N5: =M5 -> 19
A7: FIXED COSTS
A8: Tech Salaries | B8: ='Monthly P&L'!B33 -> 3000 | C8: ='Monthly P&L'!C33 -> 3000 | D8: ='Monthly P&L'!D33 -> 3000 | E8: ='Monthly P&L'!E33 -> 3000 | F8: ='Monthly P&L'!F33 -> 3000 | G8: ='Monthly P&L'!G33 -> 4500 | H8: ='Monthly P&L'!H33 -> 4500 | I8: ='Monthly P&L'!I33 -> 4500 | ... M8: ='Monthly P&L'!M33 -> 6000 | N8: =SUM(B8:M8) -> 51000
A9: Office & Admin | B9: ='Monthly P&L'!B34 -> 1500 | C9: ='Monthly P&L'!C34 -> 1500 | D9: ='Monthly P&L'!D34 -> 1500 | E9: ='Monthly P&L'!E34 -> 1500 | F9: ='Monthly P&L'!F34 -> 1500 | G9: ='Monthly P&L'!G34 -> 1500 | H9: ='Monthly P&L'!H34 -> 1500 | I9: ='Monthly P&L'!I34 -> 1500 | ... M9: ='Monthly P&L'!M34 -> 1500 | N9: =SUM(B9:M9) -> 18000
A10: Equipment | B10: ='Monthly P&L'!B35 -> 2000 | C10: ='Monthly P&L'!C35 -> 0 | D10: ='Monthly P&L'!D35 -> 0 | E10: ='Monthly P&L'!E35 -> 0 | F10: ='Monthly P&L'!F35 -> 0 | G10: ='Monthly P&L'!G35 -> 1000 | H10: ='Monthly P&L'!H35 -> 0 | I10: ='Monthly P&L'!I35 -> 0 | ... M10: ='Monthly P&L'!M35 -> 0 | N10: =SUM(B10:M10) -> 4000
A11: Total Fixed | B11: =B8+B9+B10 -> 6500 | C11: =C8+C9+C10 -> 4500 | D11: =D8+D9+D10 -> 4500 | E11: =E8+E9+E10 -> 4500 | F11: =F8+F9+F10 -> 4500 | G11: =G8+G9+G10 -> 7000 | H11: =H8+H9+H10 -> 6000 | I11: =I8+I9+I10 -> 6000 | ... M11: =M8+M9+M10 -> 7500 | N11: =SUM(B11:M11) -> 73000
A13: VARIABLE COSTS
A14: Infrastructure | B14: ='Monthly P&L'!B25 -> 877.5 | C14: ='Monthly P&L'!C25 -> 1125 | D14: ='Monthly P&L'!D25 -> 1357.5 | E14: ='Monthly P&L'!E25 -> 1597.5 | F14: ='Monthly P&L'!F25 -> 1867.5 | G14: ='Monthly P&L'!G25 -> 2167.5 | H14: ='Monthly P&L'!H25 -> 2490 | I14: ='Monthly P&L'!I25 -> 2835 | ... M14: ='Monthly P&L'!M25 -> 4357.5 | N14: =SUM(B14:M14) -> 29415
A15: Sales Commission (25% Revenue Share) | B15: ='Monthly P&L'!B26 -> 1387.5 | C15: ='Monthly P&L'!C26 -> 2625 | D15: ='Monthly P&L'!D26 -> 3787.5 | E15: ='Monthly P&L'!E26 -> 4987.5 | F15: ='Monthly P&L'!F26 -> 6337.5 | G15: ='Monthly P&L'!G26 -> 7837.5 | H15: ='Monthly P&L'!H26 -> 9450 | I15: ='Monthly P&L'!I26 -> 11175 | ... M15: ='Monthly P&L'!M26 -> 18787.5 | N15: =SUM(B15:M15) -> 111075
A16: Total Variable | B16: =B14+B15 -> 2265 | C16: =C14+C15 -> 3750 | D16: =D14+D15 -> 5145 | E16: =E14+E15 -> 6585 | F16: =F14+F15 -> 8205 | G16: =G14+G15 -> 10005 | H16: =H14+H15 -> 11940 | I16: =I14+I15 -> 14010 | ... M16: =M14+M15 -> 23145 | N16: =SUM(B16:M16) -> 140490
A18: TOTAL COSTS | B18: =B11+B16 -> 8765 | C18: =C11+C16 -> 8250 | D18: =D11+D16 -> 9645 | E18: =E11+E16 -> 11085 | F18: =F11+F16 -> 12705 | G18: =G11+G16 -> 17005 | H18: =H11+H16 -> 17940 | I18: =I11+I16 -> 20010 | ... M18: =M11+M16 -> 30645 | N18: =SUM(B18:M18) -> 213490
A19: Cost per Client | B19: =IF('Monthly P&L'!B18=0,0,B18/'Monthly P&L'!B18) -> 324.62963 | C19: =IF('Monthly P&L'!C18=0,0,C18/'Monthly P&L'!C18) -> 191.86047 | D19: =IF('Monthly P&L'!D18=0,0,D18/'Monthly P&L'!D18) -> 166.2931 | E19: =IF('Monthly P&L'!E18=0,0,E18/'Monthly P&L'!E18) -> 147.8 | F19: =IF('Monthly P&L'!F18=0,0,F18/'Monthly P&L'!F18) -> 135.15957 | G19: =IF('Monthly P&L'!G18=0,0,G18/'Monthly P&L'!G18) -> 147.86957 | H19: =IF('Monthly P&L'!H18=0,0,H18/'Monthly P&L'!H18) -> 130.94891 | I19: =IF('Monthly P&L'!I18=0,0,I18/'Monthly P&L'!I18) -> 124.28571 | ... M19: =IF('Monthly P&L'!M18=0,0,M18/'Monthly P&L'!M18) -> 116.07955

Sheet Unit Economics
A1: UNIT ECONOMICS
A2: Revenue Model
A3: Price per client | B3: 300 | C3: Monthly subscription
A4: Sales partner share (25%) | B4: =-B3*0.25 -> -75 | C4: Commission to sales network
A5: Net revenue to ALLONE | B5: =B3+B4 -> 225 | C5: What ALLONE keeps
A6: COSTS PER CLIENT
A7: Cost Structure | B7: ='Monthly P&L'!B7*'Monthly P&L'!B3 -> 15 | C7: 12% of price
A8: Fixed infrastructure (monthly) | B8: 600 | C8: Claude Code + DB + hosting
A9: Variable API cost (5%) | B9: =B3*0.05 -> 15 | C9: Per-client API usage
A10: Avg clients (Month 6) | B10: ='Monthly P&L'!G19 -> 104.5 | C10: Reference point
A11: Infrastructure per client | B11: =(B8/B10)+B9 -> 20.741627 | C11: Fixed spread + variable
A12: Gross profit per client | B12: =B5-B11 -> 204.25837 | C12: After all direct costs
A13: Avg Monthly Churn | B13: ='Client Growth'!B17 -> 0.070438542 | C13: From client data
A14: Customer Lifetime Value | B14: =IF(B13=0,24,1/B13) -> 14.196773 | C14: 1/churn rate
A15: Monthly churn rate | B15: 0.07 | C15: Average across Year 1
A16: Customer lifetime (months) | B16: =1/B15 -> 14.285714 | C16: 1 / churn rate
A17: Lifetime revenue | B17: =B3*B16 -> 4285.7143 | C17: Total billings
A18: Lifetime revenue to ALLONE | B18: =B5*B16 -> 3214.2857 | C18: After sales share
A19: Lifetime gross profit | B19: =B12*B16 -> 2917.9768 | C19: Value per customer
A20: LTV/CAC Ratio | B20: =IF(B19=0,0,B16/B19) -> 0.0048957601 | C20: >3x is healthy
A21: Capital Efficiency | B21: =IF(B10=0,0,B19/B10) -> 27.923223 | C21: CAC/Monthly margin
A22: Upfront acquisition cost | B22: 0 | C22: Commission-only model = no CAC
A23: Marketing per client | B23: =1000/345 -> 2.8985507 | C23: Y1 marketing / Y1 new clients
A24: Total acquisition cost | B24: =B22+B23 -> 2.8985507 | C24: Tech + Office + Equip
A25: Payback period (months) | B25: =IF(B24=0,0,B24/B12) -> 0.014190609 | C25: Immediate if no CAC
A26: Current Clients (M1) | B26: ='Monthly P&L'!B18 -> 27
A27: Key Metrics | B27: =IF(B26>=B25,"PROFITABLE","PRE-PROFIT") -> PROFITABLE
A28: Gross margin % | B28: =B12/B3 -> 0.68086124
A29: Net margin % (to ALLONE) | B29: =B12/B5 -> 0.90781499 | C29: On net revenue
A30: Break-even clients | B30: =('Monthly P&L'!B33+'Monthly P&L'!B34)/B12 -> 22.030921 | C30: Monthly fixed costs / Gross profit
A31: Total Costs | B31: ='Monthly P&L'!N27+'Monthly P&L'!N36 -> 213490
A32: NOTE: Traditional LTV/CAC ratio doesn't apply to this model. | B32: ='Monthly P&L'!N42 -> 195706.25
A33: Sales partners receive 25% ongoing revenue share, not one-time commission. | B33: =IF(B30=0,0,B32/B30) -> 8883.2534
A34: This eliminates upfront CAC and aligns partner incentives with retention.

Sheet Cash Flow
B1: M1 | C1: M2 | D1: M3 | E1: M4 | F1: M5 | G1: M6 | H1: M7 | I1: M8 | J1: M9 | K1: M10 | L1: M11 | M1: M12 | N1: TOTAL
A2: CASH FLOW
A3: Opening Balance | B3: 40000 | C3: =B14 -> 36785 | D3: =C14 -> 38697.5 | E3: =D14 -> 43376.75 | F3: =E14 -> 50912 | G3: =F14 -> 61660.25 | H3: =G14 -> 73853.5 | I3: =H14 -> 90734.5 | J3: =I14 -> 111721 | ... M3: =L14 -> 197877
A5: Cash In (Revenue) | B5: ='Monthly P&L'!B22 -> 5550 | C5: ='Monthly P&L'!C22 -> 10500 | D5: ='Monthly P&L'!D22 -> 15150 | E5: ='Monthly P&L'!E22 -> 19950 | F5: ='Monthly P&L'!F22 -> 25350 | G5: ='Monthly P&L'!G22 -> 31350 | H5: ='Monthly P&L'!H22 -> 37800 | I5: ='Monthly P&L'!I22 -> 44700 | ... M5: ='Monthly P&L'!M22 -> 75150 | N5: =SUM(B5:M5) -> 444300
A7: Cash Out:
A8: COGS | B8: ='Monthly P&L'!B27 -> 2265 | C8: ='Monthly P&L'!C27 -> 3750 | D8: ='Monthly P&L'!D27 -> 5145 | E8: ='Monthly P&L'!E27 -> 6585 | F8: ='Monthly P&L'!F27 -> 8205 | G8: ='Monthly P&L'!G27 -> 10005 | H8: ='Monthly P&L'!H27 -> 11940 | I8: ='Monthly P&L'!I27 -> 14010 | ... M8: ='Monthly P&L'!M27 -> 23145
A9: OpEx | B9: ='Monthly P&L'!B36 -> 6500 | C9: ='Monthly P&L'!C36 -> 4500 | D9: ='Monthly P&L'!D36 -> 4500 | E9: ='Monthly P&L'!E36 -> 4500 | F9: ='Monthly P&L'!F36 -> 4500 | G9: ='Monthly P&L'!G36 -> 7000 | H9: ='Monthly P&L'!H36 -> 6000 | I9: ='Monthly P&L'!I36 -> 6000 | ... M9: ='Monthly P&L'!M36 -> 7500
A10: Taxes | B10: ='Monthly P&L'!B41 -> 0 | C10: ='Monthly P&L'!C41 -> 337.5 | D10: ='Monthly P&L'!D41 -> 825.75 | E10: ='Monthly P&L'!E41 -> 1329.75 | F10: ='Monthly P&L'!F41 -> 1896.75 | G10: ='Monthly P&L'!G41 -> 2151.75 | H10: ='Monthly P&L'!H41 -> 2979 | I10: ='Monthly P&L'!I41 -> 3703.5 | ... M10: ='Monthly P&L'!M41 -> 6675.75
A11: Total Cash Out | B11: =B8+B9+B10 -> 8765 | C11: =C8+C9+C10 -> 8587.5 | D11: =D8+D9+D10 -> 10470.75 | E11: =E8+E9+E10 -> 12414.75 | F11: =F8+F9+F10 -> 14601.75 | G11: =G8+G9+G10 -> 19156.75 | H11: =H8+H9+H10 -> 20919 | I11: =I8+I9+I10 -> 23713.5 | ... M11: =M8+M9+M10 -> 37320.75 | N11: =SUM(B11:M11) -> 248593.75
A13: Net Cash Flow | B13: =B5-B11 -> -3215 | C13: =C5-C11 -> 1912.5 | D13: =D5-D11 -> 4679.25 | E13: =E5-E11 -> 7535.25 | F13: =F5-F11 -> 10748.25 | G13: =G5-G11 -> 12193.25 | H13: =H5-H11 -> 16881 | I13: =I5-I11 -> 20986.5 | ... M13: =M5-M11 -> 37829.25 | N13: =SUM(B13:M13) -> 195706.25
A14: Closing Balance | B14: =B3+B13 -> 36785 | C14: =C3+C13 -> 38697.5 | D14: =D3+D13 -> 43376.75 | E14: =E3+E13 -> 50912 | F14: =F3+F13 -> 61660.25 | G14: =G3+G13 -> 73853.5 | H14: =H3+H13 -> 90734.5 | I14: =I3+I13 -> 111721 | ... M14: =M3+M13 -> 235706.25 | N14: =M14 -> 235706.25
A16: METRICS
A17: Runway (months) | B17: =IF(B13>=0,"∞",IF(B11=0,0,B14/(-B13))) -> 11.44168 | C17: =IF(C13>=0,"∞",IF(C11=0,0,C14/(-C13))) -> ∞ | D17: =IF(D13>=0,"∞",IF(D11=0,0,D14/(-D13))) -> ∞ | E17: =IF(E13>=0,"∞",IF(E11=0,0,E14/(-E13))) -> ∞ | F17: =IF(F13>=0,"∞",IF(F11=0,0,F14/(-F13))) -> ∞ | G17: =IF(G13>=0,"∞",IF(G11=0,0,G14/(-G13))) -> ∞ | H17: =IF(H13>=0,"∞",IF(H11=0,0,H14/(-H13))) -> ∞ | I17: =IF(I13>=0,"∞",IF(I11=0,0,I14/(-I13))) -> ∞ | ... M17: =IF(M13>=0,"∞",IF(M11=0,0,M14/(-M13))) -> ∞
A18: Break-Even? | B18: =IF(B13>=0,"YES","NO") -> NO | C18: =IF(C13>=0,"YES","NO") -> YES | D18: =IF(D13>=0,"YES","NO") -> YES | E18: =IF(E13>=0,"YES","NO") -> YES | F18: =IF(F13>=0,"YES","NO") -> YES | G18: =IF(G13>=0,"YES","NO") -> YES | H18: =IF(H13>=0,"YES","NO") -> YES | I18: =IF(I13>=0,"YES","NO") -> YES | ... M18: =IF(M13>=0,"YES","NO") -> YES

Sheet Use of Funds
A1: STAGE 1: $40,000 (Months 1-6)
A2: Category | B2: Amount | C2: % | D2: Notes
A4: OPERATIONS
A5: Tech Team Salaries | B5: 19500 | D5: 2-3 developers × $1,500/mo × 6mo
A6: Office Rent | B6: 9000 | D6: $1,500/mo × 6 months
A7: Subtotal Operations | B7: =B5+B6 -> 28500 | C7: =B7/40000 -> 0.7125
A9: TECHNOLOGY
A10: AI Subscriptions | B10: 5000 | D10: OpenAI, Anthropic APIs
A11: Database & Hosting | B11: 1500 | D11: Supabase, cloud infrastructure
A12: Software Tools | B12: 1000 | D12: n8n, dev tools, licenses
A13: Subtotal Technology | B13: =B10+B11+B12 -> 7500 | C13: =B13/40000 -> 0.1875
A15: SETUP & GROWTH
A16: Equipment | B16: 3000 | D16: Hardware for tech team
A17: Marketing & Launch | B17: 1000 | D17: Initial outreach, branding
A18: Subtotal Setup | B18: =B16+B17 -> 4000 | C18: =B18/40000 -> 0.1
A20: TOTAL STAGE 1 | B20: =B7+B13+B18 -> 40000 | C20: =B20/40000 -> 1
A22: MILESTONE: | B22: Break-even by Month 2, 100+ clients by Month 6
A25: STAGE 2: $200,000 (Months 7-18)
A26: Category | B26: Amount | C26: % | D26: Notes
A28: INFRASTRUCTURE
A29: AI Training Servers (GPUs) | B29: 80000 | D29: Model training capability
A30: Production Servers | B30: 30000 | D30: Hosting, inference
A31: Setup & Integration | B31: 10000 | D31: Installation, configuration
A32: Subtotal Infrastructure | B32: =B29+B30+B31 -> 120000 | C32: =B32/200000 -> 0.6
A34: OPERATIONS
A35: Office Rent | B35: 12000 | D35: $1,500/mo × 8 months
A36: Additional Tech Hires | B36: 48000 | D36: 3 developers × $1,500 × ~10mo
A37: Subtotal Operations | B37: =B35+B36 -> 60000 | C37: =B37/200000 -> 0.3
A39: TECHNOLOGY
A40: AI Subscriptions (transition) | B40: 3000 | D40: Reduced after own servers
A41: Database & Hosting | B41: 2000 | D41: Production databases
A42: Equipment (3 new hires) | B42: 3000 | D42: $1,000 × 3
A43: Subtotal Technology | B43: =B40+B41+B42 -> 8000 | C43: =B43/200000 -> 0.04
A45: GROWTH & EXPANSION
A46: Regional Marketing | B46: 7000 | D46: Armenia, Azerbaijan expansion
A47: Partnership Development | B47: 3000 | D47: Local integrators, resellers
A48: Training & Onboarding | B48: 2000 | D48: New team members
A49: Subtotal Growth | B49: =B46+B47+B48 -> 12000 | C49: =B49/200000 -> 0.06
A51: TOTAL STAGE 2 | B51: =B32+B37+B43+B49 -> 200000 | C51: =B51/200000 -> 1
A53: MILESTONE: | B53: Own AI infrastructure, regional expansion, 400+ clients
...

Sheet Investment Plan
A1: Stage | B1: Amount | C1: Equity | D1: Purpose | E1: Milestone
A2: Stage 1 (Now) | B2: 40000 | C2: 10% | D2: Sales team (6→10), Office (12mo), Equipment | E2: 20+ clients, $15K/mo revenue
A3: Stage 2 | B3: 200000 | C3: 15% | D3: Own infrastructure (-50% infra), 15-20 sales, Regional expansion | E3: 100+ clients, $50K+/mo revenue
A4: Stage 3 | B4: 1000000 | C4: 15% | D4: Caucasus expansion, Full infrastructure, Product development | E4: 300+ clients, Profitable
A7: STAGE 1 BREAKDOWN
A8: Office (12 months) | B8: ='Monthly P&L'!N34 -> 18000
A9: Tech Salaries (12 months) | B9: ='Monthly P&L'!N33 -> 51000
A10: Equipment | B10: ='Monthly P&L'!N35 -> 4000
A11: Commission (Year 1) | B11: ='Monthly P&L'!N26 -> 111075
A12: Infrastructure (Year 1) | B12: ='Monthly P&L'!N25 -> 29415
A13: TOTAL COSTS | B13: ='Monthly P&L'!N27+'Monthly P&L'!N36 -> 213490
A15: Revenue (Year 1) | B15: ='Monthly P&L'!N22 -> 444300
A16: Net Profit (Year 1) | B16: ='Monthly P&L'!N42 -> 195706.25
A18: Max Cash Deficit | B18: =MIN('Cash Flow'!B14:M14)-'Cash Flow'!B3 -> -3215
A19: Investment Provided | B19: 40000
A20: Safety Buffer | B20: =B19-ABS(B18) -> 36785

Sheet 3-Year Scenarios
B1: Year 1 | C1: Year 2 | D1: Year 3
A2: BASE CASE
A3: Clients (end) | B3: ='Monthly P&L'!M18 -> 264 | C3: 442 | D3: 685
A4: Sales Team | B4: ='Monthly P&L'!M10 -> 15 | C4: 20 | D4: 30
A5: Tech Team | B5: ='Monthly P&L'!M11 -> 4 | C5: 6 | D5: 8
A6: Revenue | B6: ='Monthly P&L'!N22 -> 444300 | C6: =B3*12*300 -> 950400 | D6: =C3*12*300 -> 1591200
A7: Gross Profit | B7: ='Monthly P&L'!N29 -> 303810 | C7: =C6*0.63 -> 598752 | D7: =D6*0.63 -> 1002456
A8: Net Profit | B8: ='Monthly P&L'!N42 -> 195706.25 | C8: =C7-100000 -> 498752 | D8: =D7-150000 -> 852456
A9: Net Margin % | B9: =IF(B6=0,0,B8/B6) -> 0.44048222 | C9: =IF(C6=0,0,C8/C6) -> 0.52478114 | D9: =IF(D6=0,0,D8/D6) -> 0.53573152
A10: Infra Cost/Client | B10: ='Monthly P&L'!B7*'Monthly P&L'!B3 -> 15 | C10: =B10*0.5 -> 7.5 | D10: =C10 -> 7.5
A11: Market | B11: Georgia | C11: Georgia+ | D11: Caucasus
A13: SCENARIOS (Y1)
A14: Deals/Person | B14: 2.5 | C14: 3 | D14: 3.5
A15: Total New Clients | B15: =B14*15*12*0.7 -> 315 | C15: =C14*15*12*0.7 -> 378 | D15: =D14*15*12*0.7 -> 441
A16: Y1 Clients (end) | B16: =ROUND(B15*0.75,0) -> 236 | C16: =ROUND(C15*0.75,0) -> 284 | D16: =ROUND(D15*0.75,0) -> 331
A17: Y1 Revenue | B17: =(10+B16)/2*12*300 -> 442800 | C17: =(10+C16)/2*12*300 -> 529200 | D17: =(10+D16)/2*12*300 -> 613800
A18: Y1 Net Profit | B18: =B17*0.63-90000 -> 188964 | C18: =C17*0.63-90000 -> 243396 | D18: =D17*0.63-90000 -> 296694
